Workbook

Sheet Portada
A2: RFP — Request for Proposal
A3: Transformación Digital — Inversora de Capilla S.A.
A4: OpenSource Consulting · Grupo 3 · FCE-UBA · 2026
A6: Empresa solicitante | B6: Inversora de Capilla S.A.
A7: Consultora | B7: OpenSource Consulting
A8: Responsable sponsor | B8: Ramiro Illa y socio
A9: Fecha de emisión | B9: Junio, 2026
A10: Versión | B10: v4
A11: Ponderación global | B11: Funcional 45% | Técnico 15% | Económico 20% | Proveedor 20%

Sheet Introducción
A2: Metodología adoptada | B2: TOGAF ADM | D2: Supuestos de evaluación
B3: Modelo de Innovación de Doblin | D3: Horizonte de evaluación: 3 años.
D4: Cantidad estimada: 5-15 usuarios.
D5: Modelo SaaS Cloud First.
A6: Matriz de ponderación | D6: Operación Argentina.
B8: Dimensión del RFP | C8: Ponderación | D8: Foco Crítico de Evaluación
B10: Aspecto Funcional | C10: 0.45 | D10: Capacidad de cobertura del CRM comercial, embudo de ventas, repositorio documental unificado, automatización financiera y módulos de control de obra en campo.
B11: Aspecto Técnico | C11: 0.15 | D11: Cumplimiento del modelo 100% SaaS nube, APIs de integración abierta, seguridad avanzada (MFA, RBAC), cifrado de datos (Ley 25.326) y disponibilidad del 99.5% uptime.
B12: Aspecto Económico | C12: 0.2 | D12: Análisis del Costo Total de Propiedad (TCO) proyectado a 3 años, diferenciando claramente la inversión inicial (CAPEX) del costo operativo mensual de las suscripciones (OPEX).
B13: Aspecto Proveedor | C13: 0.2 | D13: Idoneidad y experiencia en los sectores de Real Estate / PropTech, solidez legal y fiscal en Argentina (facturación ARS / AFIP) y planes estructurados de soporte con penalidades.
A16: Escalas | B16: NAT. | C16: - Lo tiene de manera nativa | D16: 1
B17: INC. | C17: - No lo tiene pero nos lo incluye si lo compramos | D17: 0.75
B18: CONF. | C18: - No lo tiene pero es configurable (cotizable) | D18: 0.5
B19: DES. | C19: - No lo tiene pero lo puede desarrollar | D19: 0.25
B20: N/A | C20: - No lo tiene / ni lo puede desarrollar | D20: 0
B22: — NOTA ACLARATORIA SOBRE USO DE ESCALAS —
B23: Aspectos Funcional y Técnico
B24: Las escalas NAT/INC/CONF/DES/N/A evalúan si la plataforma posee la funcionalidad o el atributo técnico de forma nativa, si puede incluirlo con adquisición de módulo adicional, si es configurable, si debe desarrollarse a medida o si directamente no lo ofrece ni puede ofrecerlo.
B26: Aspecto Económico — Escala adaptada
B27: Puntaje | C27: Descripción | D27: Ejemplos : | E27: Coste Total de Propiedad (TCO) a 3 años
B28: 1 | C28: Muy competitivo | E28: Puntaje | F28: TCO
B29: 0.75 | C29: Competitivo | E29: 1 | F29: ≤ USD 10.000
B30: 0.5 | C30: Aceptable | E30: 0.75 | F30: USD 10.001–15.000
B31: 0.25 | C31: Elevado | E31: 0.5 | F31: USD 15.001–20.000
B32: 0 | C32: Inviable | E32: 0.25 | F32: USD 20.001–25.000
E33: 0 | F33: > USD 25.000
B34: Certificaciones
B35: Puntaje | C35: Condición | E35: Licencias
B36: 0 | C36: Sin certificaciones | E36: Puntaje | F36: Licencia mensual
B37: 0.5 | C37: ISO 27001 o equivalente | E37: 1 | F37: ≤ USD 50 por usuario
B38: 1 | C38: ISO 27001 + SOC 2 + otras certificaciones relevantes | E38: 0.75 | F38: USD 51–75
E39: 0.5 | F39: USD 76–100
B40: Experiencia en la Industria | E40: 0.25 | F40: USD 101–150
B41: (Aplica a experiencia inmobiliaria, construcción, PyMEs similares) | E41: 0 | F41: > USD 150
B42: Cumplimiento | C42: Criterio
B43: 1 | C43: Más de 10 casos comprobables en la industria o segmento
B44: 0.75 | C44: Entre 5 y 10 casos
B45: 0.5 | C45: Entre 2 y 4 casos
B46: 0.25 | C46: 1 caso documentado
B47: 0 | C47: Sin referencias relevantes
...

Sheet Matriz Funcional
B2: ASPECTO FUNCIONAL | C2: Ponderación | D2: Peso relativo | E2: Detalle | F2: Comentarios | G2: Justificación | H2: MS Dynamics 365 | K2: Zoho One
C3: 0.45 | H3: Puntaje | I3: Puntaje Ponderado | J3: Aporte Relativo | K3: Puntaje | L3: Puntaje Ponderado | M3: Aporte Relativo
B4: A. CRM — Gestión de Relaciones con el Cliente | C4: 0.4 | D4: =C3*C4 -> 0.18 | I4: =SUM(I5+I9+I14+I18)*C4 -> 0.39 | J4: =SUM(J5+J9+J14+J18) -> 0.1755 | L4: =SUM(L5+L9+L14+L18)*C4 -> 0.39 | M4: =SUM(M5+M9+M14+M18) -> 0.1755
B5: 1. Gestión de Contactos y Cuentas | C5: 0.2 | D5: =C3*C4*C5 -> 0.036 | I5: =SUM(I6:I8)*C5 -> 0.2 | J5: =SUM(J6:J8) -> 0.036 | L5: =SUM(L6:L8)*C5 -> 0.2 | M5: =SUM(M6:M8) -> 0.036
B6: 1.1 Ficha 360° del cliente | C6: 0.4 | D6: =0.45*C4*C5*C6 -> 0.0144 | E6: Vista unificada del cliente: datos personales, propiedades de interés, operaciones realizadas e historial completo. | F6: Inversora de Capilla no tiene hoy un perfil unificado de cliente; la info está en WhatsApp, papel y planillas. | G6: Base del CRM: sin ficha 360° no existe trazabilidad comercial ni operativa. | H6: 1 | I6: =H6*C6 -> 0.4 | J6: =I6*D5 -> 0.0144 | K6: 1 | L6: =K6*C6 -> 0.4 | M6: =L6*D5 -> 0.0144
B7: 1.2 Segmentación de clientes | C7: 0.3 | D7: =0.45*C4*C5*C7 -> 0.0108 | E7: Capacidad de crear segmentos y listas dinámicas por criterios: zona, tipo de propiedad, estado del ciclo, perfil inversor. | F7: Permite personalizar campañas y priorizar el seguimiento según el perfil del comprador. | G7: La segmentación es prerequisito de toda estrategia de marketing y retención. | H7: 1 | I7: =H7*C7 -> 0.3 | J7: =I7*D5 -> 0.0108 | K7: 1 | L7: =K7*C7 -> 0.3 | M7: =L7*D5 -> 0.0108
B8: 1.3 Historial completo y trazabilidad | C8: 0.3 | D8: =0.45*C4*C5*C8 -> 0.0108 | E8: Registro cronológico de todas las interacciones: llamadas, reuniones, mails, visitas a obra y documentación compartida. | H8: 1 | I8: =H8*C8 -> 0.3 | J8: =I8*D5 -> 0.0108 | K8: 1 | L8: =K8*C8 -> 0.3 | M8: =L8*D5 -> 0.0108
B9: 2. Gestión Comercial y Pipeline | C9: 0.3 | D9: =C3*C4*C9 -> 0.054 | I9: =SUM(I10:I13)*C9 -> 0.3 | J9: =SUM(J10:J13) -> 0.054 | L9: =SUM(L10:L13)*C9 -> 0.3 | M9: =SUM(M10:M13) -> 0.054
B10: 2.1 CRM centralizado (leads, oportunidades, cuentas) | C10: 0.3 | D10: =0.45*C4*C9*C10 -> 0.0162 | E10: Gestión de leads entrantes, conversión a oportunidades y seguimiento de cuentas activas desde una plataforma única. | F10: Reemplaza el seguimiento disperso en WhatsApp y 6 planillas Excel. | G10: Núcleo del CRM — sin esta funcionalidad no existe transformación comercial. | H10: 1 | I10: =H10*C10 -> 0.3 | J10: =I10*D9 -> 0.0162 | K10: 1 | L10: =K10*C10 -> 0.3 | M10: =L10*D9 -> 0.0162
B11: 2.2 Pipeline de ventas con etapas y probabilidad de cierre | C11: 0.25 | D11: =0.45*C4*C9*C11 -> 0.0135 | E11: Embudo comercial configurable: etapas, propietarios, fechas estimadas y probabilidad de conversión por oportunidad. | H11: 1 | I11: =H11*C11 -> 0.25 | J11: =I11*D9 -> 0.0135 | K11: 1 | L11: =K11*C11 -> 0.25 | M11: =L11*D9 -> 0.0135
B12: 2.3 Lead scoring y calificación automática | C12: 0.2 | D12: =0.45*C4*C9*C12 -> 0.0108 | E12: Puntuación automática de leads según comportamiento, origen, perfil y engagement para priorizar el equipo de ventas. | F12: Con 40-70 leads potenciales simultáneos, la priorización manual genera pérdida de oportunidades. | G12: Maximiza el ROI del equipo comercial reduciendo el tiempo dedicado a leads no calificados. | H12: 1 | I12: =H12*C12 -> 0.2 | J12: =I12*D9 -> 0.0108 | K12: 1 | L12: =K12*C12 -> 0.2 | M12: =L12*D9 -> 0.0108
B13: 2.4 Automatización de workflows comerciales | C13: 0.25 | D13: =0.45*C4*C9*C13 -> 0.0135 | E13: Reglas automáticas: asignación de leads, envío de recordatorios, creación de tareas y actualización de estados sin intervención manual. | F13: Actualmente cada paso comercial requiere acción manual, generando omisiones y desvíos. | G13: Componente clave de la automatización comercial — reduce carga sobre el equipo de ventas. | H13: 1 | I13: =H13*C13 -> 0.25 | J13: =I13*D9 -> 0.0135 | K13: 1 | L13: =K13*C13 -> 0.25 | M13: =L13*D9 -> 0.0135
B14: 3. Marketing y Campañas | C14: 0.25 | D14: =C3*C4*C14 -> 0.045 | I14: =SUM(I15:I17)*C14 -> 0.25 | J14: =SUM(J15:J17) -> 0.045 | L14: =SUM(L15:L17)*C14 -> 0.25 | M14: =SUM(M15:M17) -> 0.045
B15: 3.1 Segmentación y listas dinámicas para campañas | C15: 0.35 | D15: =0.45*C4*C14*C15 -> 0.01575 | E15: Definición de audiencias dinámicas para campañas basadas en atributos del CRM (zona, estado, interés, historial). | F15: Permite comunicar la oferta correcta al cliente correcto en el momento adecuado. | G15: Sin segmentación dinámica, las campañas pierden precisión y generan fatiga en los contactos. | H15: 1 | I15: =H15*C15 -> 0.35 | J15: =I15*D14 -> 0.01575 | K15: 1 | L15: =K15*C15 -> 0.35 | M15: =L15*D14 -> 0.01575
B16: 3.2 Campañas masivas multi-canal (email / WhatsApp) | C16: 0.4 | D16: =0.45*C4*C14*C16 -> 0.018 | E16: Ejecución de campañas de comunicación masiva desde el CRM hacia los canales preferidos del cliente. | F16: Hoy la comunicación es manual, uno a uno, por WhatsApp personal de cada vendedor. | G16: Escala el alcance comercial sin escalar la estructura de personal. | H16: 1 | I16: =H16*C16 -> 0.4 | J16: =I16*D14 -> 0.018 | K16: 1 | L16: =K16*C16 -> 0.4 | M16: =L16*D14 -> 0.018
B17: 3.3 Trazabilidad multicanal del cliente | C17: 0.25 | D17: =0.45*C4*C14*C17 -> 0.01125 | E17: Registro unificado de interacciones por email, WhatsApp, llamadas y visitas en el perfil del cliente. | H17: 1 | I17: =H17*C17 -> 0.25 | J17: =I17*D14 -> 0.01125 | K17: 1 | L17: =K17*C17 -> 0.25 | M17: =L17*D14 -> 0.01125
B18: 4. Postventa y Fidelización | C18: 0.25 | D18: =C3*C4*C18 -> 0.045 | I18: =SUM(I19:I20)*C18 -> 0.225 | J18: =SUM(J19+J20) -> 0.0405 | L18: =SUM(L19:L20)*C18 -> 0.225 | M18: =SUM(M19:M20) -> 0.0405
B19: 4.1 Gestión postventa y satisfacción del cliente | C19: 0.6 | D19: =0.45*C4*C18*C19 -> 0.027 | E19: Seguimiento de compradores post-entrega: relevamiento de satisfacción, gestión de reclamos y alertas de vencimientos. | H19: 1 | I19: =H19*C19 -> 0.6 | J19: =I19*D18 -> 0.027 | K19: 1 | L19: =K19*C19 -> 0.6 | M19: =L19*D18 -> 0.027
B20: 4.2 Portal o historial de servicio post-entrega | C20: 0.4 | D20: =0.45*C4*C18*C20 -> 0.018 | E20: Acceso del cliente a documentación, comprobantes, estado de obra y comunicaciones históricas. | F20: Reduce consultas recurrentes al equipo y mejora la percepción de transparencia. | G20: Diferenciador de propuesta de valor para un mercado donde la confianza es clave. | H20: 0.75 | I20: =H20*C20 -> 0.3 | J20: =I20*D18 -> 0.0135 | K20: 0.75 | L20: =K20*C20 -> 0.3 | M20: =L20*D18 -> 0.0135
B21: B. BI — Business Intelligence | C21: 0.2 | D21: =0.45*C21 -> 0.09 | I21: =SUM(I22+I25+I29+I32)*C21 -> 0.2 | J21: =SUM(J22+J25+J29+J32) -> 0.09 | L21: =SUM(L22+L25+L29+L32)*C21 -> 0.177 | M21: =SUM(M22+M25+M29+M32) -> 0.07965
B22: 5. Integración de Datos y Repositorio Analítico | C22: 0.2 | D22: =0.45*C21*C22 -> 0.018 | I22: =SUM(I23:I24)*C22 -> 0.2 | J22: =SUM(J23+J23) -> 0.018 | L22: =SUM(L23:L24)*C22 -> 0.175 | M22: =SUM(M23+M24) -> 0.01575
B23: 5.1 ETL / Conectores nativos desde CRM, proyectos y finanzas | C23: 0.5 | D23: =0.45*C21*C22*C23 -> 0.009 | E23: Capacidad de extraer, transformar y cargar datos desde los módulos operativos al repositorio analítico sin intervención manual. | F23: Sin ETL, el BI requiere exportaciones manuales periódicas desde las planillas. | G23: Prerequisito técnico para cualquier análisis actualizado y confiable. | H23: 1 | I23: =H23*C23 -> 0.5 | J23: =I23*D22 -> 0.009 | K23: 1 | L23: =K23*C23 -> 0.5 | M23: =L23*D22 -> 0.009
B24: 5.2 Repositorio analítico unificado (data mart / DWH básico) | C24: 0.5 | D24: =0.45*C21*C22*C24 -> 0.009 | E24: Modelo de datos histórico y consistente que centraliza métricas de ventas, costos, proyectos y clientes para análisis. | F24: Un repositorio unificado elimina la contradicción de datos entre áreas. | G24: Fundamento del análisis multidimensional y la toma de decisiones basada en datos. | H24: 1 | I24: =H24*C24 -> 0.5 | J24: =I24*D22 -> 0.009 | K24: 0.75 | L24: =K24*C24 -> 0.375 | M24: =L24*D22 -> 0.00675
B25: 6. Análisis, Visualización e Indicadores | C25: 0.4 | D25: =0.45*C21*C25 -> 0.036 | I25: =SUM(I26:I28)*C25 -> 0.4 | J25: =SUM(J26:J28) -> 0.036 | L25: =SUM(L26:L28)*C25 -> 0.335 | M25: =SUM(M26:M28) -> 0.03015
B26: 6.1 Dashboards ejecutivos con KPIs configurables | C26: 0.4 | D26: =0.45*C21*C25*C26 -> 0.0144 | E26: Paneles interactivos con indicadores clave: ventas, rentabilidad por proyecto, avance de obra y flujo de caja en tiempo real. | F26: Hoy las decisiones se toman sin datos consolidados; los directivos no tienen visibilidad unificada. | G26: Impacto directo en calidad de decisiones estratégicas. | H26: 1 | I26: =H26*C26 -> 0.4 | J26: =I26*D25 -> 0.0144 | K26: 0.75 | L26: =K26*C26 -> 0.3 | M26: =L26*D25 -> 0.0108
B27: 6.2 Reportes estándar y personalizados por área | C27: 0.35 | D27: =0.45*C21*C25*C27 -> 0.0126 | E27: Generación de informes por área (comercial, financiero, obra) con filtros, exportación y programación de envío. | F27: Elimina el armado manual de reportes en Excel que hoy consume horas semanales del equipo. | G27: Libera tiempo operativo y mejora la exactitud de la información reportada. | H27: 1 | I27: =H27*C27 -> 0.35 | J27: =I27*D25 -> 0.0126 | K27: 1 | L27: =K27*C27 -> 0.35 | M27: =L27*D25 -> 0.0126
B28: 6.3 Análisis ad-hoc y drill-down por dimensión | C28: 0.25 | D28: =0.45*C21*C25*C28 -> 0.009 | E28: Capacidad del usuario de explorar datos dinámicamente (por zona, período, proyecto, vendedor) sin depender de IT. | F28: Permite responder preguntas no planificadas ante situaciones concretas de negocio. | G28: Autoservicio analítico — requisito de madurez básico para una empresa en transformación. | H28: 1 | I28: =H28*C28 -> 0.25 | J28: =I28*D25 -> 0.009 | K28: 0.75 | L28: =K28*C28 -> 0.1875 | M28: =L28*D25 -> 0.00675
B29: 7. Alertas y Proyecciones | C29: 0.25 | D29: =0.45*C21*C29 -> 0.0225 | I29: =SUM(I30:I31)*C29 -> 0.25 | J29: =SUM(J30:J31) -> 0.0225 | L29: =SUM(L30:L31)*C29 -> 0.225 | M29: =SUM(M30:M31) -> 0.02025
B30: 7.1 Alertas automáticas ante desvíos de KPIs | C30: 0.6 | D30: =0.45*C21*C29*C30 -> 0.0135 | E30: Notificaciones proactivas cuando indicadores superan umbrales: retraso de obra, caída de conversión, déficit de caja. | F30: Elimina el control manual con planillas estáticas que detectan problemas tarde. | G30: Control preventivo — reduce impacto de desvíos al identificarlos tempranamente. | H30: 1 | I30: =H30*C30 -> 0.6 | J30: =I30*D29 -> 0.0135 | K30: 1 | L30: =K30*C30 -> 0.6 | M30: =L30*D29 -> 0.0135
B31: 7.2 Forecasting y proyecciones básicas de ventas/costos | C31: 0.4 | D31: =0.45*C21*C29*C31 -> 0.009 | E31: Proyecciones automáticas de ventas, costos y rentabilidad basadas en el historial y el pipeline actual. | F31: Inversora de Capilla toma decisiones de inversión sin proyecciones formales. | G31: Crítico para la planificación financiera y la gestión de riesgo de proyectos. | H31: 1 | I31: =H31*C31 -> 0.4 | J31: =I31*D29 -> 0.009 | K31: 0.75 | L31: =K31*C31 -> 0.3 | M31: =L31*D29 -> 0.00675
B32: 8. Distribución y Acceso | C32: 0.15 | D32: =0.45*C21*C32 -> 0.0135 | I32: =SUM(I33:I34)*C32 -> 0.15 | J32: =SUM(J33:J34) -> 0.0135 | L32: =SUM(L33:L34)*C32 -> 0.15 | M32: =SUM(M33:M34) -> 0.0135
B33: 8.1 Acceso móvil a dashboards y reportes | C33: 0.6 | D33: =0.45*C21*C32*C33 -> 0.0081 | E33: Visualización y navegación de indicadores desde smartphones y tablets. | F33: Los directivos operan desde Los Cardales — el acceso móvil es requisito operativo. | G33: Alineado con el requisito cloud-first y la gestión remota. | H33: 1 | I33: =H33*C33 -> 0.6 | J33: =I33*D32 -> 0.0081 | K33: 1 | L33: =K33*C33 -> 0.6 | M33: =L33*D32 -> 0.0081
B34: 8.2 Exportación y distribución programada de informes | C34: 0.4 | D34: =0.45*C21*C32*C34 -> 0.0054 | E34: Envío automático de reportes por email a frecuencias configurables (semanal, mensual). | F34: Garantiza que los directivos reciban información sin tener que acceder activamente al sistema. | G34: Mejora la adopción del BI al llevar los datos a donde ya trabaja el equipo. | H34: 1 | I34: =H34*C34 -> 0.4 | J34: =I34*D32 -> 0.0054 | K34: 1 | L34: =K34*C34 -> 0.4 | M34: =L34*D32 -> 0.0054
B35: C. MDM — Gestión de Datos Maestros | C35: 0.1 | D35: =0.45*C35 -> 0.045 | I35: =SUM(I36+I40)*C35 -> 0.0925 | J35: =SUM(J36+J40) -> 0.041625 | L35: =SUM(L36+L40)*C35 -> 0.075 | M35: =SUM(M36+M40) -> 0.03375
B36: 9. Repositorio Único de Entidades | C36: 0.5 | D36: =0.45*C35*C36 -> 0.0225 | I36: =SUM(I37:I39)*C36 -> 0.425 | J36: =SUM(J37:J39) -> 0.019125 | L36: =SUM(L37:L39)*C36 -> 0.375 | M36: =SUM(M37:M39) -> 0.016875
B37: 9.1 Golden record del cliente (entidad única) | C37: 0.4 | D37: =0.45*C35*C36*C37 -> 0.009 | E37: Registro único, deduplicado y autoritativo de cada cliente, usado por todos los módulos del sistema. | F37: Hoy la misma persona puede existir en múltiples planillas con datos inconsistentes. | G37: Es la condición para que el CRM, BI y Finanzas hablen del mismo cliente. | H37: 1 | I37: =H37*C37 -> 0.4 | J37: =I37*D36 -> 0.009 | K37: 0.75 | L37: =K37*C37 -> 0.3 | M37: =L37*D36 -> 0.00675
B38: 9.2 Maestro de proyectos y propiedades | C38: 0.3 | D38: =0.45*C35*C36*C38 -> 0.00675 | E38: Catálogo único de proyectos, unidades y propiedades con sus atributos, estados y referencias cruzadas. | F38: Sin un maestro único, los mismos proyectos tienen datos distintos en CRM, obra y finanzas. | G38: Prerequisito para la gestión integrada del ciclo del proyecto inmobiliario. | H38: 0.75 | I38: =H38*C38 -> 0.225 | J38: =I38*D36 -> 0.0050625 | K38: 0.75 | L38: =K38*C38 -> 0.225 | M38: =L38*D36 -> 0.0050625
B39: 9.3 Maestro de contratistas y proveedores | C39: 0.3 | D39: =0.45*C35*C36*C39 -> 0.00675 | E39: Registro centralizado de contratistas y proveedores con datos de contacto, categoría, historial y habilitaciones. | F39: Hoy hay 40-70 contratistas sin un registro formal ni estandarizado. | G39: Permite gestionar contratos, pagos y seguimiento de obra desde una fuente única. | H39: 0.75 | I39: =H39*C39 -> 0.225 | J39: =I39*D36 -> 0.0050625 | K39: 0.75 | L39: =K39*C39 -> 0.225 | M39: =L39*D36 -> 0.0050625
B40: 10. Calidad y Gobierno de Datos | C40: 0.5 | D40: =0.45*C35*C40 -> 0.0225 | I40: =SUM(I41:I43)*C40 -> 0.5 | J40: =SUM(J41:J43) -> 0.0225 | L40: =SUM(L41:L43)*C40 -> 0.375 | M40: =SUM(M41:M43) -> 0.016875
B41: 10.1 Deduplicación y normalización de registros | C41: 0.35 | D41: =0.45*C35*C40*C41 -> 0.007875 | E41: Detección y fusión automática de registros duplicados; normalización de campos clave (nombres, direcciones, CUIT). | F41: La migración desde 6 planillas generará inevitablemente duplicados sin herramientas de limpieza. | G41: Calidad del dato desde el día 1 — impacta directamente en la confianza del sistema. | H41: 1 | I41: =H41*C41 -> 0.35 | J41: =I41*D40 -> 0.007875 | K41: 0.75 | L41: =K41*C41 -> 0.2625 | M41: =L41*D40 -> 0.00590625
...

Sheet Matriz Técnica
B2: ASPECTO TECNICO | C2: Ponderación | D2: Peso relativo | E2: Detalle | F2: Comentarios | G2: Justificación | H2: MS Dynamics 365 | K2: Zoho One
C3: 0.15 | H3: Puntaje | I3: Puntaje Ponderado | J3: Aporte Relativo | K3: Puntaje | L3: Puntaje Ponderado | M3: Aporte Relativo
B4: A. Infraestructura | C4: 0.2 | D4: =C4*C3 -> 0.03 | I4: =SUM(I5+I10+I14)*C4 -> 0.2 | J4: =SUM(J5+J10+J14) -> 0.03 | L4: =SUM(L5+L10+L14)*C4 -> 0.2 | M4: =SUM(M5+M10+M14) -> 0.03
B5: 1. Cloud | C5: 0.5 | D5: =C5*C4*C3 -> 0.015 | I5: =SUM(I6:I9)*C5 -> 0.5 | J5: =SUM(J6:J9) -> 0.015 | L5: =SUM(L6:L9)*C5 -> 0.5 | M5: =SUM(M6:M9) -> 0.015
B6: 1.1 Despliegue SaaS Multi-Tenant | C6: 0.4 | D6: =C3*C4*C5*C6 -> 0.006 | E6: Plataforma alojada en la nube del proveedor, accesible desde cualquier navegador sin instalación local. El proveedor gestiona infraestructura, actualizaciones y mantenimiento. | F6: Inversora de Capilla no cuenta con infraestructura IT propia ni personal técnico interno — el modelo SaaS elimina ese requisito desde el inicio. | G6: El mandato cloud-first del RFP excluye soluciones on-premise; el SaaS multi-tenant garantiza actualizaciones automáticas y costos predecibles de operación. | H6: 1 | I6: =H6*C6 -> 0.4 | J6: =I6*D5 -> 0.006 | K6: 1 | L6: =K6*C6 -> 0.4 | M6: =L6*D5 -> 0.006
B7: 1.2 Alta disponibilidad (HA) | C7: 0.4 | D7: =C3*C4*C5*C7 -> 0.006 | E7: Arquitectura con redundancia activa que minimiza el tiempo de inactividad no planificado mediante failover automático entre nodos o regiones. | F7: Una caída del sistema durante el proceso de venta de una unidad puede generar pérdida de la operación y deterioro inmediato de la confianza del cliente. | G7: La alta disponibilidad es prerrequisito operativo para una empresa cuyo negocio core depende de la plataforma — sin ella el modelo digital pierde su promesa de valor. | H7: 1 | I7: =H7*C7 -> 0.4 | J7: =I7*D5 -> 0.006 | K7: 1 | L7: =K7*C7 -> 0.4 | M7: =L7*D5 -> 0.006
B8: 1.3 Escalabilidad automática | C8: 0.1 | D8: =C3*C4*C5*C8 -> 0.0015 | E8: Capacidad de la plataforma de ajustar automáticamente los recursos de cómputo ante picos de demanda sin intervención manual ni degradación del servicio. | F8: Aunque hoy son 5-15 usuarios, la empresa prevé crecer en volumen de proyectos y personal; la plataforma debe acompañar ese crecimiento sin migraciones costosas. | G8: Evita la necesidad de re-implementaciones al escalar y protege la inversión inicial — clave en una empresa en etapa de transformación y crecimiento. | H8: 1 | I8: =H8*C8 -> 0.1 | J8: =I8*D5 -> 0.0015 | K8: 1 | L8: =K8*C8 -> 0.1 | M8: =L8*D5 -> 0.0015
B9: 1.4 SLA ≥ 99,9% | C9: 0.1 | D9: =C3*C4*C5*C9 -> 0.0015 | E9: Compromiso contractual del proveedor de disponibilidad mínima del 99,9% mensual, equivalente a menos de 9 horas de inactividad no planificada al año. | F9: El RFP establece como requisito técnico un uptime de 99,5%; el nivel de exigencia 99,9% representa el estándar de referencia del mercado SaaS empresarial. | G9: Un SLA formalizado con penalidades establece responsabilidad del proveedor y protege a Inversora de Capilla ante interrupciones que afecten operaciones comerciales. | H9: 1 | I9: =H9*C9 -> 0.1 | J9: =I9*D5 -> 0.0015 | K9: 1 | L9: =K9*C9 -> 0.1 | M9: =L9*D5 -> 0.0015
B10: 2. Acceso | C10: 0.35 | D10: =C10*C4*C3 -> 0.0105 | I10: =SUM(I11:I13)*C10 -> 0.35 | J10: =SUM(J11:J13) -> 0.0105 | L10: =SUM(L11:L13)*C10 -> 0.35 | M10: =SUM(M11:M13) -> 0.0105
B11: 2.1 Acceso Web | C11: 0.6 | D11: =C3*C4*C10*C11 -> 0.0063 | E11: Interfaz de usuario accesible desde cualquier navegador estándar (Chrome, Firefox, Edge, Safari) sin plugins adicionales ni requisitos de sistema operativo específico. | F11: El equipo opera desde Buenos Aires y Los Cardales; el acceso web universal elimina barreras de dispositivo y ubicación para toda la operación. | G11: Requisito base del modelo cloud-first — sin acceso web universal no existe movilidad operativa ni la posibilidad de trabajar desde múltiples locaciones. | H11: 1 | I11: =H11*C11 -> 0.6 | J11: =I11*D10 -> 0.0063 | K11: 1 | L11: =K11*C11 -> 0.6 | M11: =L11*D10 -> 0.0063
B12: 2.2 Aplicación móvil | C12: 0.1 | D12: =C3*C4*C10*C12 -> 0.00105 | E12: Aplicación nativa o PWA para iOS y Android que permite operar las funcionalidades clave desde smartphones y tablets sin degradación de la experiencia de usuario. | F12: Los directivos y responsables de obra en Los Cardales requieren acceso móvil para operar sin depender de una PC de escritorio en campo. | G12: La operación en campo es un caso de uso central de Inversora de Capilla — sin app móvil funcional se pierden los beneficios del modelo digital para obra. | H12: 1 | I12: =H12*C12 -> 0.1 | J12: =I12*D10 -> 0.00105 | K12: 1 | L12: =K12*C12 -> 0.1 | M12: =L12*D10 -> 0.00105
B13: 2.3 Soporte multiplataforma | C13: 0.3 | D13: =C3*C4*C10*C13 -> 0.00315 | E13: Compatibilidad verificada con los principales sistemas operativos (Windows, macOS, Android, iOS) y navegadores del mercado sin pérdida de funcionalidad. | F13: El equipo de Inversora de Capilla usa distintos dispositivos sin un estándar corporativo definido — la diversidad tecnológica del equipo es la norma. | G13: La diversidad de dispositivos en una PyME sin IT hace crítica la compatibilidad amplia para garantizar adopción real y evitar exclusiones involuntarias. | H13: 1 | I13: =H13*C13 -> 0.3 | J13: =I13*D10 -> 0.00315 | K13: 1 | L13: =K13*C13 -> 0.3 | M13: =L13*D10 -> 0.00315
B14: 3. Rendimiento | C14: 0.15 | D14: =C14*C4*C3 -> 0.0045 | I14: =SUM(I15:I16)*C14 -> 0.15 | J14: =SUM(J15:J16) -> 0.0045 | L14: =SUM(L15:L16)*C14 -> 0.15 | M14: =SUM(M15:M16) -> 0.0045
B15: 3.1 Tiempo de respuesta configurable | C15: 0.5 | D15: =C3*C4*C14*C15 -> 0.00225 | E15: Capacidad de ajustar parámetros de performance (timeouts, caché, frecuencia de actualización) según necesidades operativas y condiciones de conectividad de la empresa. | F15: Conexiones desde Los Cardales pueden tener latencia variable — la configurabilidad permite adaptar la plataforma a esas condiciones de conectividad. | G15: La performance percibida impacta directamente en la tasa de adopción del sistema — un sistema lento es un sistema abandonado. | H15: 1 | I15: =H15*C15 -> 0.5 | J15: =I15*D14 -> 0.00225 | K15: 1 | L15: =K15*C15 -> 0.5 | M15: =L15*D14 -> 0.00225
B16: 3.2 Monitoreo de performance | C16: 0.5 | D16: =C3*C4*C14*C16 -> 0.00225 | E16: Panel o dashboard de métricas de performance del sistema: tiempos de carga, disponibilidad, errores y uso de recursos en tiempo real o near-real-time. | F16: Sin monitoreo, los problemas de performance solo se detectan cuando ya afectan al usuario; el diagnóstico proactivo reduce el impacto operativo. | G16: Habilita la gestión proactiva de la plataforma y la comunicación formal con el proveedor ante incumplimientos de SLA — condición de accountability técnico. | H16: 1 | I16: =H16*C16 -> 0.5 | J16: =I16*D14 -> 0.00225 | K16: 1 | L16: =K16*C16 -> 0.5 | M16: =L16*D14 -> 0.00225
B17: B. Integración | C17: 0.3 | D17: =C17*C3 -> 0.045 | I17: =SUM(I18+I22+I27)*C17 -> 0.282186 | J17: =SUM(J18+J22+J27) -> 0.0423279 | L17: =SUM(L18+L22+L27)*C17 -> 0.25937362 | M17: =SUM(M22+M27+M29) -> 0.03740625
B18: 4. APIs | C18: 0.05 | D18: =C18*C17*C3 -> 0.00225 | I18: =SUM(I19:I21)*C18 -> 0.049995 | J18: =SUM(J19+J20+J21) -> 0.002249775 | L18: =SUM(L19:L21)*C18 -> 0.04582875 | M18: =SUM(M19:M21) -> 0.0020622937
B19: 4.1 APIs REST nativas | C19: 0.3333 | D19: =C3*C17*C18*C19 -> 0.000749925 | E19: Conjunto de endpoints REST publicados nativamente por la plataforma para acceso programático a entidades, operaciones y datos desde sistemas externos. | F19: Inversora de Capilla puede necesitar integrar portales inmobiliarios (Properati, Zonaprop) o sistemas contables externos vía API en una segunda fase. | G19: Las APIs REST son el estándar de integración del ecosistema SaaS — su ausencia cierra la posibilidad de conectar con cualquier herramienta de terceros. | H19: 1 | I19: =H19*C19 -> 0.3333 | J19: =I19*D18 -> 0.000749925 | K19: 1 | L19: =K19*C19 -> 0.3333 | M19: =L19*D18 -> 0.000749925
B20: 4.2 APIs documentadas | C20: 0.3333 | D20: =C3*C17*C18*C20 -> 0.000749925 | E20: Documentación técnica completa y actualizada de los endpoints REST: especificación OpenAPI/Swagger, ejemplos de uso, autenticación y límites de tasa. | F20: Una API sin documentación adecuada requiere ingeniería inversa costosa, elevando el costo de integración para cualquier partner implementador o desarrollo interno. | G20: La calidad de la documentación define la velocidad y el costo de cualquier integración futura — es determinante del TCO real más allá del precio de lista. | H20: 1 | I20: =H20*C20 -> 0.3333 | J20: =I20*D18 -> 0.000749925 | K20: 0.75 | L20: =K20*C20 -> 0.249975 | M20: =L20*D18 -> 0.00056244375
B21: 4.3 Webhooks | C21: 0.3333 | D21: =C3*C17*C18*C21 -> 0.000749925 | E21: Mecanismo de notificación push que dispara llamadas HTTP a sistemas externos ante eventos internos de la plataforma (nuevo lead, cambio de estado, pago registrado). | F21: Los webhooks permiten automatizar flujos con herramientas externas (Zapier, Make, sistemas propios) sin polling constante que consuma recursos. | G21: Habilitan integraciones en tiempo real más eficientes que el polling periódico, reduciendo complejidad y costo operativo de cualquier integración futura. | H21: 1 | I21: =H21*C21 -> 0.3333 | J21: =I21*D18 -> 0.000749925 | K21: 1 | L21: =K21*C21 -> 0.3333 | M21: =L21*D18 -> 0.000749925
B22: 5. Datos | C22: 0.85 | D22: =C22*C17*C3 -> 0.03825 | I22: =SUM(I23:I26)*C22 -> 0.796875 | J22: =SUM(J23:J26) -> 0.035859375 | L22: =SUM(L23:L26)*C22 -> 0.74375 | M22: =SUM(M23:M26) -> 0.03346875
B23: 5.1 Importación masiva | C23: 0.25 | D23: =C3*C17*C22*C23 -> 0.0095625 | E23: Herramienta nativa para carga masiva de registros desde archivos CSV, Excel u otros formatos estructurados hacia las entidades clave de la plataforma. | F23: La migración desde las 6 planillas Excel actuales requiere importación masiva — sin esta capacidad la carga inicial es manual, lenta y propensa a errores. | G23: Condición técnica para que la migración de datos históricos sea viable, rápida y confiable desde el día 1 de operación del nuevo sistema. | H23: 1 | I23: =H23*C23 -> 0.25 | J23: =I23*D22 -> 0.0095625 | K23: 1 | L23: =K23*C23 -> 0.25 | M23: =L23*D22 -> 0.0095625
B24: 5.2 Exportación masiva | C24: 0.25 | D24: =C3*C17*C22*C24 -> 0.0095625 | E24: Capacidad de extraer la totalidad de los propios datos en formatos estándar (CSV, Excel, JSON) sin restricciones de volumen ni dependencia del proveedor. | F24: El derecho a exportar los propios datos es un principio de soberanía de datos — crítico para evitar vendor lock-in y proteger la continuidad del negocio. | G24: Protege ante un cambio de proveedor y garantiza el cumplimiento de la Ley 25.326 sobre habeas data y portabilidad de la información. | H24: 1 | I24: =H24*C24 -> 0.25 | J24: =I24*D22 -> 0.0095625 | K24: 1 | L24: =K24*C24 -> 0.25 | M24: =L24*D22 -> 0.0095625
B25: 5.3 ETL / ELT | C25: 0.25 | D25: =C3*C17*C22*C25 -> 0.0095625 | E25: Pipelines nativos o conectores certificados para extraer, transformar y cargar datos entre la plataforma y repositorios analíticos externos de forma automatizada. | F25: Sin ETL automatizado, el BI requiere exportaciones manuales periódicas que consumen tiempo y generan datos desactualizados para la toma de decisiones. | G25: Es el prerrequisito técnico para el análisis en tiempo real y la construcción de un repositorio analítico unificado — base del BI mencionado en el aspecto funcional. | H25: 1 | I25: =H25*C25 -> 0.25 | J25: =I25*D22 -> 0.0095625 | K25: 0.75 | L25: =K25*C25 -> 0.1875 | M25: =L25*D22 -> 0.007171875
B26: 5.4 Sincronización bidireccional | C26: 0.25 | D26: =C3*C17*C22*C26 -> 0.0095625 | E26: Capacidad de mantener datos coherentes en tiempo real entre la plataforma y sistemas externos (contabilidad, portales, ERP) con actualización en ambas direcciones. | F26: Un registro actualizado en el CRM debe reflejarse automáticamente en el sistema contable y viceversa — sin esto hay doble carga manual y riesgo de inconsistencias. | G26: Elimina la necesidad de mantener datos en paralelo en múltiples sistemas, reduciendo errores de ingreso y carga operativa del equipo administrativo. | H26: 0.75 | I26: =H26*C26 -> 0.1875 | J26: =I26*D22 -> 0.007171875 | K26: 0.75 | L26: =K26*C26 -> 0.1875 | M26: =L26*D22 -> 0.007171875
B27: 6. Ecosistema | C27: 0.1 | D27: =C27*C17*C3 -> 0.0045 | I27: =SUM(I28:I31)*C27 -> 0.09375 | J27: =SUM(J28:J31) -> 0.00421875 | L27: =SUM(L28:L31)*C27 -> 0.075 | M27: =SUM(M28:M31) -> 0.003375
B28: 6.1 Microsoft 365 | C28: 0.25 | D28: =C3*C17*C27*C28 -> 0.001125 | E28: Integración nativa con el ecosistema Microsoft 365: sincronización de correo (Outlook), calendario (Teams/Calendar), OneDrive y almacenamiento de documentos. | F28: Si el equipo ya usa Outlook o Teams, la integración reduce la curva de adopción al conectar el CRM con herramientas que el equipo ya conoce y utiliza a diario. | G28: Microsoft 365 es el entorno de productividad más difundido en PyMEs argentinas — la integración nativa acelera la adopción y reduce la resistencia al cambio. | H28: 1 | I28: =H28*C28 -> 0.25 | J28: =I28*D27 -> 0.001125 | K28: 0.75 | L28: =K28*C28 -> 0.1875 | M28: =L28*D27 -> 0.00084375
B29: 6.2 Power BI | C29: 0.25 | D29: =C3*C17*C27*C29 -> 0.001125 | E29: Conector certificado con Microsoft Power BI para visualización avanzada de datos y construcción de reportes personalizados sobre los datos de la plataforma. | F29: Si la empresa ya utiliza o planea incorporar Power BI, la integración nativa evita duplicar el esfuerzo de análisis y extrae mayor valor del dato ya capturado. | G29: Power BI es la herramienta de BI más utilizada en el segmento empresarial; la integración nativa amplía las capacidades analíticas sin costo adicional de desarrollo. | H29: 1 | I29: =H29*C29 -> 0.25 | J29: =I29*D27 -> 0.001125 | K29: 0.5 | L29: =K29*C29 -> 0.125 | M29: =L29*D27 -> 0.0005625
B30: 6.3 Google Workspace | C30: 0.25 | D30: =C3*C17*C27*C30 -> 0.001125 | E30: Integración nativa con Google Workspace: sincronización de Gmail, Google Calendar, Google Drive y Google Meet para el equipo que use este ecosistema. | F30: Una parte del equipo puede usar Gmail y Google Calendar como herramientas primarias — la integración sincroniza actividad sin duplicación manual de registros. | G30: Google Workspace es alternativa frecuente en PyMEs; la integración garantiza flexibilidad ante distintas preferencias tecnológicas del equipo. | H30: 0.75 | I30: =H30*C30 -> 0.1875 | J30: =I30*D27 -> 0.00084375 | K30: 1 | L30: =K30*C30 -> 0.25 | M30: =L30*D27 -> 0.001125
B31: 6.4 ERP externos | C31: 0.25 | D31: =C3*C17*C27*C31 -> 0.001125 | E31: Conectores o adaptadores para integración con sistemas ERP presentes en el mercado argentino (Tango Gestión, Bejerman, SAP B1 u otros de uso frecuente local). | F31: Inversora de Capilla puede tener o incorporar un sistema contable/ERP — la integración evita doble carga de datos entre el CRM y la herramienta contable. | G31: La coexistencia de CRM y ERP es frecuente en PyMEs argentinas — la integración nativa reduce el costo total de integración y los errores de doble ingreso. | H31: 1 | I31: =H31*C31 -> 0.25 | J31: =I31*D27 -> 0.001125 | K31: 0.75 | L31: =K31*C31 -> 0.1875 | M31: =L31*D27 -> 0.00084375
B32: C. Seguridad | C32: 0.35 | D32: =C32*C3 -> 0.0525 | I32: =SUM(I33+I37+I40+I45)*C32 -> 0.35 | J32: =SUM(J33+J40+J37+J45) -> 0.0525 | L32: =SUM(L33+L37+L40+L45)*C32 -> 0.314125 | M32: =SUM(M33+M40+M37+M45) -> 0.04711875
B33: 7. Identidad | C33: 0.4 | D33: =C33*C32*C3 -> 0.021 | I33: =SUM(I34:I36)*C33 -> 0.4 | J33: =SUM(J34:J36) -> 0.021 | L33: =SUM(L34:L36)*C33 -> 0.36 | M33: =SUM(M34:M36) -> 0.0189
B34: 7.1 MFA | C34: 0.6 | D34: =C3*C32*C33*C34 -> 0.0126 | E34: Autenticación multifactor obligatoria o configurable mediante código SMS, autenticador TOTP (Google/Microsoft Authenticator) o llaves de seguridad físicas. | F34: Inversora de Capilla maneja datos de clientes con CUIT, DNI y datos patrimoniales — el MFA es la primera línea de defensa ante accesos no autorizados. | G34: Requisito explícito del RFP en el aspecto técnico; el MFA es el control de identidad más efectivo contra ataques de credential stuffing y phishing. | H34: 1 | I34: =H34*C34 -> 0.6 | J34: =I34*D33 -> 0.0126 | K34: 1 | L34: =K34*C34 -> 0.6 | M34: =L34*D33 -> 0.0126
B35: 7.2 SSO | C35: 0.3 | D35: =C3*C32*C33*C35 -> 0.0063 | E35: Single Sign-On que permite acceder a la plataforma con las mismas credenciales corporativas (Microsoft, Google) sin gestionar contraseñas adicionales. | F35: El SSO simplifica la gestión de accesos y reduce la fricción de adopción para el equipo — una credencial menos que recordar y gestionar. | G35: Mejora la experiencia del usuario y centraliza la gestión de identidad, reduciendo el riesgo de contraseñas débiles o reutilizadas en cuentas sensibles. | H35: 1 | I35: =H35*C35 -> 0.3 | J35: =I35*D33 -> 0.0063 | K35: 0.75 | L35: =K35*C35 -> 0.225 | M35: =L35*D33 -> 0.004725
B36: 7.3 Integración con Azure AD | C36: 0.1 | D36: =C3*C32*C33*C36 -> 0.0021 | E36: Integración nativa con Azure Active Directory / Microsoft Entra ID para autenticación federada, gestión de grupos y políticas de acceso corporativas. | F36: Relevante si la empresa escala hacia el ecosistema Microsoft 365; permite gestionar usuarios desde un directorio centralizado sin duplicar la administración. | G36: Azure AD es el directorio corporativo más extendido en el mercado empresarial argentino — la integración nativa es un diferenciador de madurez técnica en evaluación. | H36: 1 | I36: =H36*C36 -> 0.1 | J36: =I36*D33 -> 0.0021 | K36: 0.75 | L36: =K36*C36 -> 0.075 | M36: =L36*D33 -> 0.001575
B37: 8. Autorización | C37: 0.3 | D37: =C37*C32*C3 -> 0.01575 | I37: =SUM(I38:I39)*C37 -> 0.3 | J37: =SUM(J38:J39) -> 0.01575 | L37: =SUM(L38:L39)*C37 -> 0.2625 | M37: =SUM(M38:M39) -> 0.01378125
B38: 8.1 RBAC | C38: 0.5 | D38: =C3*C32*C37*C38 -> 0.007875 | E38: Control de acceso basado en roles (Role-Based Access Control) que define qué funcionalidades y datos puede ver o modificar cada perfil de usuario de la plataforma. | F38: En Inversora de Capilla coexisten perfiles distintos (director, vendedor, responsable de obra, administrador) con necesidades de acceso claramente diferenciadas. | G38: Requisito explícito del RFP; el RBAC garantiza que cada usuario vea solo lo que necesita, reduciendo riesgos de modificaciones no autorizadas sobre datos críticos. | H38: 1 | I38: =H38*C38 -> 0.5 | J38: =I38*D37 -> 0.007875 | K38: 1 | L38: =K38*C38 -> 0.5 | M38: =L38*D37 -> 0.007875
B39: 8.2 Roles personalizables | C39: 0.5 | D39: =C3*C32*C37*C39 -> 0.007875 | E39: Capacidad de crear y modificar roles a medida, más allá de los perfiles predefinidos, para adaptarse a la estructura organizativa específica de la empresa. | F39: La estructura de Inversora de Capilla no responde a jerarquías corporativas estándar — roles rígidos pueden no mapear correctamente sus necesidades operativas reales. | G39: Los roles personalizables garantizan que los controles de acceso reflejen la realidad operativa sin forzar adaptaciones estructurales en la empresa. | H39: 1 | I39: =H39*C39 -> 0.5 | J39: =I39*D37 -> 0.007875 | K39: 0.75 | L39: =K39*C39 -> 0.375 | M39: =L39*D37 -> 0.00590625
B40: 9. Datos | C40: 0.2 | D40: =C40*C32*C3 -> 0.0105 | I40: =SUM(I41:I44)*C40 -> 0.2 | J40: =SUM(J41:J44) -> 0.0105 | L40: =SUM(L41:L44)*C40 -> 0.175 | M40: =SUM(M41:M44) -> 0.0091875
B41: 9.1 Cifrado en tránsito (TLS) | C41: 0.25 | D41: =C3*C32*C40*C41 -> 0.002625 | E41: Toda la comunicación entre el cliente (navegador/app) y los servidores de la plataforma está cifrada con TLS 1.2 o superior, sin excepciones. | F41: El tráfico de datos sensibles (datos de clientes, operaciones, documentos) sobre redes públicas o móviles requiere cifrado para evitar interceptación. | G41: TLS es el estándar mínimo de seguridad en comunicaciones web; su ausencia invalida cualquier declaración de seguridad de la plataforma en el mercado actual. | H41: 1 | I41: =H41*C41 -> 0.25 | J41: =I41*D40 -> 0.002625 | K41: 1 | L41: =K41*C41 -> 0.25 | M41: =L41*D40 -> 0.002625
...

Sheet Matriz Económica
B2: ASPECTO ECONOMICO | C2: Ponderación | D2: Peso relativo | E2: Detalle | F2: Comentarios | G2: Justificación | H2: MS Dynamics 365 | K2: Zoho One
C3: 0.2 | H3: Puntaje | I3: Puntaje Ponderado | J3: Aporte Relativo | K3: Puntaje | L3: Puntaje Ponderado | M3: Aporte Relativo
B4: A. Costos iniciales de adquisición | C4: 0.4 | D4: =C3*C4 -> 0.08 | I4: =SUM(I5+I10)*C4 -> 0.225 | J4: =SUM(J5+J10) -> 0.045 | L4: =SUM(L5+L10)*C4 -> 0.3625 | M4: =SUM(M5+M10) -> 0.0725
B5: 1. Licenciamiento | C5: 0.5 | D5: =C3*C4*C5 -> 0.04 | I5: =SUM(I6:I9)*C5 -> 0.28125 | J5: =SUM(J6:J9) -> 0.0225 | L5: =SUM(L6:L9)*C5 -> 0.4375 | M5: =SUM(M6:M9) -> 0.035
B6: 1.1 Costo por usuario | C6: 0.25 | D6: =C3*C4*C5*C6 -> 0.01 | E6: Precio mensual por usuario activo en el plan base de la plataforma, en modalidad SaaS, expresado en USD o ARS según política del proveedor. | F6: Con 5-15 usuarios en el escenario de Inversora de Capilla, el costo por usuario es el principal driver del OPEX mensual de la plataforma. | G6: El costo por usuario define la accesibilidad económica del modelo para una PyME argentina con presupuesto acotado en contexto de alta inflación. | H6: 0.25 | I6: =H6*C6 -> 0.0625 | J6: =I6*D5 -> 0.0025 | K6: 0.75 | L6: =K6*C6 -> 0.1875 | M6: =L6*D5 -> 0.0075
B7: 1.2 Costo por administrador | C7: 0.25 | D7: =C3*C4*C5*C7 -> 0.01 | E7: Diferenciación de precio entre usuarios estándar y usuarios administradores o con acceso a módulos premium, si la plataforma establece esta distinción. | F7: Algunos proveedores cobran diferente por usuarios con permisos de administración — esto puede elevar el costo si los directivos necesitan acceso completo. | G7: Una estructura de precios que penaliza la administración dificulta la autogestión y eleva el TCO real frente al precio de lista publicado. | H7: 0.75 | I7: =H7*C7 -> 0.1875 | J7: =I7*D5 -> 0.0075 | K7: 1 | L7: =K7*C7 -> 0.25 | M7: =L7*D5 -> 0.01
B8: 1.3 Licencias incluidas | C8: 0.25 | D8: =C3*C4*C5*C8 -> 0.01 | E8: Cantidad de módulos, funcionalidades y aplicaciones incluidas en el precio base sin cargos adicionales — cobertura real del paquete base contratado. | F8: Un precio base bajo con módulos clave excluidos puede resultar más caro que un plan all-inclusive al sumar los add-ons necesarios para la operación. | G8: La exhaustividad del paquete base determina el costo real de la solución — un modelo modular fragmentado eleva el TCO de forma no prevista en la propuesta. | H8: 0.5 | I8: =H8*C8 -> 0.125 | J8: =I8*D5 -> 0.005 | K8: 1 | L8: =K8*C8 -> 0.25 | M8: =L8*D5 -> 0.01
B9: 1.4 Escalabilidad de licencias | C9: 0.25 | D9: =C3*C4*C5*C9 -> 0.01 | E9: Flexibilidad para agregar o reducir usuarios sin penalidades significativas ni contratos de largo plazo, adaptándose al crecimiento o contracción del equipo. | F9: Una empresa en crecimiento como Inversora de Capilla necesita poder escalar el número de usuarios sin renegociar contratos complejos con el proveedor. | G9: La elasticidad del licenciamiento es crítica para una PyME cuyo equipo puede crecer rápido — la rigidez contractual genera costos ocultos de crecimiento. | H9: 0.75 | I9: =H9*C9 -> 0.1875 | J9: =I9*D5 -> 0.0075 | K9: 0.75 | L9: =K9*C9 -> 0.1875 | M9: =L9*D5 -> 0.0075
B10: 2. Implementación | C10: 0.5 | D10: =C3*C4*C10 -> 0.04 | I10: =SUM(I11:I14)*C10 -> 0.28125 | J10: =SUM(J11:J14) -> 0.0225 | L10: =SUM(L11:L14)*C10 -> 0.46875 | M10: =SUM(M11:M14) -> 0.0375
B11: 2.1 Setup inicial | C11: 0.25 | D11: =C3*C4*C5*C11 -> 0.01 | E11: Costo único de configuración inicial: creación del entorno, setup base y activación del tenant, cobrado por el proveedor o su partner implementador. | F11: El setup inicial es un CAPEX que impacta en la liquidez inicial del proyecto — debe ser transparente y predecible desde la propuesta del proveedor. | G11: Los costos de setup varían ampliamente entre proveedores (desde $0 hasta miles de USD) y son determinantes del costo real total del primer año de operación. | H11: 0.75 | I11: =H11*C11 -> 0.1875 | J11: =I11*D10 -> 0.0075 | K11: 1 | L11: =K11*C11 -> 0.25 | M11: =L11*D10 -> 0.01
B12: 2.2 Parametrización | C12: 0.25 | D12: =C3*C4*C5*C12 -> 0.01 | E12: Costo de configuración a medida: adaptación de flujos, campos, formularios y reglas de negocio específicas de Inversora de Capilla a la plataforma elegida. | F12: Cuanto más parametrización requiera la plataforma para el contexto inmobiliario argentino, mayor será el CAPEX inicial de implementación del proyecto. | G12: La parametrización inicial es el principal CAPEX variable — su estimación precisa define si el proyecto es viable dentro del presupuesto asignado. | H12: 0.25 | I12: =H12*C12 -> 0.0625 | J12: =I12*D10 -> 0.0025 | K12: 0.75 | L12: =K12*C12 -> 0.1875 | M12: =L12*D10 -> 0.0075
B13: 2.3 Migración de datos | C13: 0.25 | D13: =C3*C4*C5*C13 -> 0.01 | E13: Costo del proceso de extracción, limpieza, transformación y carga de los datos existentes (6 planillas Excel) hacia la nueva plataforma. | F13: La migración de datos históricos de clientes, proyectos y operaciones es crítica para no perder trazabilidad al pasar al nuevo sistema — y tiene un costo real. | G13: Un costo de migración elevado o mal estimado puede convertirse en el principal obstáculo económico del proyecto de transformación digital. | H13: 0.75 | I13: =H13*C13 -> 0.1875 | J13: =I13*D10 -> 0.0075 | K13: 1 | L13: =K13*C13 -> 0.25 | M13: =L13*D10 -> 0.01
B14: 2.4 Integraciones iniciales | C14: 0.25 | D14: =C3*C4*C5*C14 -> 0.01 | E14: Costo de desarrollo o configuración de las integraciones necesarias desde el día 1: sistemas contables, portales inmobiliarios o herramientas ya en uso. | F14: Si las integraciones clave no están incluidas en el setup, su costo adicional puede superar el precio de licencia del primer año de operación. | G14: Las integraciones iniciales son el costo oculto más frecuente en implementaciones SaaS — su estimación explícita es condición de comparabilidad real entre propuestas. | H14: 0.5 | I14: =H14*C14 -> 0.125 | J14: =I14*D10 -> 0.005 | K14: 1 | L14: =K14*C14 -> 0.25 | M14: =L14*D10 -> 0.01
B15: B. Costos operativos y mantenimiento | C15: 0.4 | D15: =C3*C15 -> 0.08 | I15: =SUM(I16+I19+I23)*C15 -> 0.31332 | J15: =SUM(J16+J19+J23) -> 0.062664 | L15: =SUM(L16+L19+L23)*C15 -> 0.35332 | M15: =SUM(M16+M19+M23) -> 0.070664
B16: 3. Suscripción | C16: 0.4 | D16: =C3*C15*C16 -> 0.032 | I16: =SUM(I17:I18)*C16 -> 0.25 | J16: =SUM(J17:J18) -> 0.02 | L16: =SUM(L17:L18)*C16 -> 0.4 | M16: =SUM(M17:M18) -> 0.032
B17: 3.1 Pago mensual | C17: 0.5 | D17: =C3*C15*C16*C17 -> 0.016 | E17: Precio de la suscripción en modalidad mensual sin compromiso anual, que ofrece mayor flexibilidad pero generalmente a un precio unitario más elevado. | F17: La modalidad mensual es preferible en contextos de alta inflación o incertidumbre — permite salir del contrato sin penalidades si la solución no cumple. | G17: En el contexto económico argentino, la flexibilidad del pago mensual tiene valor real aunque implique un precio nominal mayor al compromiso anual. | H17: 0.75 | I17: =H17*C17 -> 0.375 | J17: =I17*D16 -> 0.012 | K17: 1 | L17: =K17*C17 -> 0.5 | M17: =L17*D16 -> 0.016
B18: 3.2 Pago anual | C18: 0.5 | D18: =C3*C15*C16*C17 -> 0.016 | E18: Precio de la suscripción en modalidad anual prepagada, que generalmente ofrece un descuento del 15-20% sobre la tarifa mensual equivalente. | F18: El pago anual reduce el OPEX mensual pero implica un desembolso inicial mayor y un compromiso de 12 meses con el proveedor seleccionado. | G18: La relación precio anual/mensual define el incentivo a comprometerse con el proveedor — un descuento significativo mejora el TCO proyectado a 3 años. | H18: 0.5 | I18: =H18*C18 -> 0.25 | J18: =I18*D16 -> 0.008 | K18: 1 | L18: =K18*C18 -> 0.5 | M18: =L18*D16 -> 0.016
B19: 4. Infraestructura | C19: 0.4 | D19: =C3*C15*C19 -> 0.032 | I19: =SUM(I20:I22)*C19 -> 0.3333 | J19: =SUM(J20:J22) -> 0.026664 | L19: =SUM(L20:L22)*C19 -> 0.3333 | M19: =SUM(M20:M22) -> 0.026664
B20: 4.1 Hosting | C20: 0.3333 | D20: =C3*C15*C19*C20 -> 0.0106656 | E20: Costo del alojamiento en la nube del proveedor, generalmente incluido en la suscripción SaaS — se evalúa si hay cargos adicionales por región o disponibilidad. | F20: En el modelo SaaS el hosting debe estar incluido — cualquier cargo separado por hosting eleva el TCO real respecto al precio de lista publicado. | G20: La transparencia en el costo de hosting es un indicador de honestidad en el pricing — los cargos ocultos de infraestructura son una señal de alerta comercial. | H20: 1 | I20: =H20*C20 -> 0.3333 | J20: =I20*D19 -> 0.0106656 | K20: 1 | L20: =K20*C20 -> 0.3333 | M20: =L20*D19 -> 0.0106656
B21: 4.2 Almacenamiento | C21: 0.3333 | D21: =C3*C15*C19*C21 -> 0.0106656 | E21: Límite de almacenamiento incluido en el plan base y costo por GB adicional — relevante dado el volumen de planos, documentos y fotos de obra previsto. | F21: El almacenamiento de planos, documentación técnica y fotos de obra puede superar rápidamente los límites del plan base si no se considera desde el inicio. | G21: El costo de almacenamiento adicional es un OPEX creciente que puede distorsionar el TCO proyectado si no se incluye en la estimación inicial del proyecto. | H21: 1 | I21: =H21*C21 -> 0.3333 | J21: =I21*D19 -> 0.0106656 | K21: 0.75 | L21: =K21*C21 -> 0.249975 | M21: =L21*D19 -> 0.0079992
B22: 4.3 Consumo adicional | C22: 0.3333 | D22: =C3*C15*C19*C22 -> 0.0106656 | E22: Cargos variables por uso intensivo: cantidad de registros, transacciones de API, envíos de email masivo u otras métricas de consumo fuera del plan base. | F22: Los cargos por consumo adicional son el componente más impredecible del TCO — generan facturas sorpresivas que dificultan la planificación presupuestaria. | G22: La previsibilidad del OPEX es crítica en una PyME argentina con presupuesto ajustado — los modelos de pricing por consumo generan incertidumbre financiera real. | H22: 0.5 | I22: =H22*C22 -> 0.16665 | J22: =I22*D19 -> 0.0053328 | K22: 0.75 | L22: =K22*C22 -> 0.249975 | M22: =L22*D19 -> 0.0079992
B23: 5. Soporte | C23: 0.2 | D23: =C3*C15*C23 -> 0.016 | I23: =SUM(I24:I25)*C23 -> 0.2 | J23: =SUM(J24:J25) -> 0.016 | L23: =SUM(L24:L25)*C23 -> 0.15 | M23: =SUM(M24:M25) -> 0.012
B24: 5.1 Soporte estándar | C24: 0.5 | D24: =C3*C15*C23*C24 -> 0.008 | E24: Plan de soporte incluido en la suscripción base: canales disponibles (email, chat, teléfono), horarios de atención y SLA de respuesta estándar garantizado. | F24: El soporte estándar define el nivel de asistencia disponible sin costo adicional — su calidad es determinante para una empresa sin IT propio. | G24: Evaluar el soporte incluido evita descubrir tardíamente que la asistencia necesaria solo está disponible en planes premium con costo adicional significativo. | H24: 1 | I24: =H24*C24 -> 0.5 | J24: =I24*D23 -> 0.008 | K24: 1 | L24: =K24*C24 -> 0.5 | M24: =L24*D23 -> 0.008
B25: 5.2 Soporte premium | C25: 0.5 | D25: =C3*C15*C23*C25 -> 0.008 | E25: Costo y cobertura del plan de soporte avanzado: SLA garantizado, gestor de cuenta dedicado, onboarding personalizado y prioridad en resolución de incidentes. | F25: Para una PyME sin IT interno, el soporte premium puede ser una inversión justificada si el estándar no garantiza tiempos de respuesta operativamente aceptables. | G25: El diferencial de precio entre soporte estándar y premium debe evaluarse contra el riesgo operativo de no tener asistencia prioritaria en momentos críticos. | H25: 1 | I25: =H25*C25 -> 0.5 | J25: =I25*D23 -> 0.008 | K25: 0.5 | L25: =K25*C25 -> 0.25 | M25: =L25*D23 -> 0.004
B26: C. Costos de Evolución | C26: 0.2 | D26: =C3*C26 -> 0.04 | I26: =SUM(I27+I31)*C26 -> 0.09999 | J26: =SUM(J27+J31) -> 0.019998 | L26: =SUM(L27+L31)*C26 -> 0.183315 | M26: =SUM(M27+M31) -> 0.036663
B27: 6. Crecimiento | C27: 0.5 | D27: =C3*C26*C27 -> 0.02 | I27: =SUM(I28:I30)*C27 -> 0.2083125 | J27: =SUM(J28:J30) -> 0.0083325 | L27: =SUM(L28:L30)*C27 -> 0.4582875 | M27: =SUM(M28:M30) -> 0.0183315
B28: 6.1 Usuarios adicionales | C28: 0.3333 | D28: =C3*C26*C27*C28 -> 0.006666 | E28: Precio unitario de agregar usuarios más allá del plan base contratado, incluyendo posibles cambios de tier o renegociaciones de contrato necesarias. | F28: Si Inversora de Capilla crece de 5 a 15 usuarios, el costo incremental por usuario define si el plan actual es sostenible o requiere migrar a un tier superior. | G28: El costo de escalar usuarios es un proxy del costo de crecimiento del negocio — debe ser lineal y predecible para no sorprender en la planificación financiera. | H28: 0.25 | I28: =H28*C28 -> 0.083325 | J28: =I28*D27 -> 0.0016665 | K28: 0.75 | L28: =K28*C28 -> 0.249975 | M28: =L28*D27 -> 0.0049995
B29: 6.2 Módulos adicionales | C29: 0.3333 | D29: =C3*C26*C27*C29 -> 0.006666 | E29: Precio de activar módulos o funcionalidades no incluidas en el plan base, como firma digital, inteligencia artificial o gestión documental avanzada. | F29: La necesidad de agregar módulos clave post-implementación puede duplicar el costo inicial del proyecto si no se evalúa en la propuesta original del proveedor. | G29: Los módulos adicionales son el mecanismo de upselling más frecuente en SaaS — su precio y disponibilidad deben evaluarse como parte del TCO a 3 años. | H29: 0.25 | I29: =H29*C29 -> 0.083325 | J29: =I29*D27 -> 0.0016665 | K29: 1 | L29: =K29*C29 -> 0.3333 | M29: =L29*D27 -> 0.006666
B30: 6.3 Ambientes adicionales | C30: 0.3333 | D30: =C3*C26*C27*C30 -> 0.006666 | E30: Costo de contar con entornos separados para pruebas o staging, además del ambiente de producción incluido en el plan base del proveedor. | F30: Un ambiente de pruebas separado permite testear configuraciones sin riesgo sobre datos productivos — práctica recomendada aunque tenga costo adicional. | G30: Operar sin ambiente de pruebas en una PyME es aceptable inicialmente, pero el costo de incorporarlo debe conocerse para la planificación futura del sistema. | H30: 0.75 | I30: =H30*C30 -> 0.249975 | J30: =I30*D27 -> 0.0049995 | K30: 1 | L30: =K30*C30 -> 0.3333 | M30: =L30*D27 -> 0.006666
B31: 7. Desarrollo | C31: 0.5 | D31: =C3*C26*C31 -> 0.02 | I31: =SUM(I32:I34)*C31 -> 0.2916375 | J31: =SUM(J32:J34) -> 0.0116655 | L31: =SUM(L32:L34)*C31 -> 0.4582875 | M31: =SUM(M32:M34) -> 0.0183315
B32: 7.1 Customizaciones | C32: 0.3333 | D32: =C3*C26*C31*C32 -> 0.006666 | E32: Costo de desarrollo de funcionalidades a medida o adaptaciones específicas del negocio no cubiertas por la configuración estándar de la plataforma. | F32: Las customizaciones tienen un costo de desarrollo inicial y un costo de mantenimiento futuro ante cada actualización de la plataforma — deben minimizarse. | G32: Cada customización introduce deuda técnica y dependencia del proveedor — su costo real incluye el mantenimiento a lo largo del ciclo de vida del sistema. | H32: 0.25 | I32: =H32*C32 -> 0.083325 | J32: =I32*D31 -> 0.0016665 | K32: 0.75 | L32: =K32*C32 -> 0.249975 | M32: =L32*D31 -> 0.0049995
B33: 7.2 Automatizaciones | C33: 0.3333 | D33: =C3*C26*C31*C33 -> 0.006666 | E33: Costo de crear o ampliar automatizaciones de flujos de trabajo más allá de las incluidas en el plan, por servicios del proveedor o desarrollo propio. | F33: Las automatizaciones son el componente de mayor ROI en la transformación digital — su costo de implementación debe evaluarse contra el ahorro operativo generado. | G33: Una plataforma que cobra caro por automatizaciones desincentiva su uso, limitando uno de los principales beneficios concretos de la digitalización. | H33: 0.5 | I33: =H33*C33 -> 0.16665 | J33: =I33*D31 -> 0.003333 | K33: 1 | L33: =K33*C33 -> 0.3333 | M33: =L33*D31 -> 0.006666
B34: 7.3 APIs adicionales | C34: 0.3333 | D34: =C3*C26*C31*C34 -> 0.006666 | E34: Costo de consumo de APIs más allá del límite incluido en el plan, o de acceder a APIs avanzadas disponibles solo en tiers superiores de la plataforma. | F34: Si las integraciones con portales inmobiliarios o sistemas externos requieren alto volumen de llamadas API, el costo adicional puede ser significativo. | G34: El costo de APIs adicionales define la viabilidad económica de integraciones futuras — debe evaluarse en el contexto del roadmap de integración de la empresa. | H34: 1 | I34: =H34*C34 -> 0.3333 | J34: =I34*D31 -> 0.006666 | K34: 1 | L34: =K34*C34 -> 0.3333 | M34: =L34*D31 -> 0.006666
B35: TOTAL | C35: =C4+C15+C26 -> 1 | D35: =D4+D15+D26 -> 0.2 | I35: =I4+I15+I26 -> 0.63831 | J35: =J4+J15+J26 -> 0.127662 | L35: =L4+L15+L26 -> 0.899135 | M35: =M4+M15+M26 -> 0.179827
B38: Categoría | C38: Peso
B39: Costos iniciales de adquisición | C39: 0.4
B40: Costos operativos y mantenimiento | C40: 0.4
B41: Costos de Evolución | C41: 0.2
B43: Escalas:
B45: Aspecto Económico — Escala adaptada | E45: Costo por usuario
...

Sheet Matriz Proveedores
B2: ASPECTO PROVEEDOR | C2: Ponderación | D2: Peso relativo | E2: Detalle | F2: Comentarios | G2: Justificación | H2: MS Dynamics 365 | K2: Zoho One
C3: 0.2 | H3: Puntaje | I3: Puntaje Ponderado | J3: Aporte Relativo | K3: Puntaje | L3: Puntaje Ponderado | M3: Aporte Relativo
B4: A. Trayectoria y solidez | C4: 0.25 | D4: =C3*C4 -> 0.05 | I4: =SUM(I5+I9+I12)*C4 -> 0.24302361 | J4: =SUM(J5+J9+J12) -> 0.048604722 | L4: =SUM(L5+L9+L12)*C4 -> 0.21524931 | M4: =SUM(M5+M9+M12) -> 0.043049861
B5: 1. Trayectoria | C5: 0.3333 | D5: =C3*C4*C5 -> 0.016665 | I5: =SUM(I6:I8)*C5 -> 0.30549445 | J5: =SUM(J6:J8) -> 0.015274722 | L5: =SUM(L6:L8)*C5 -> 0.27772222 | M5: =SUM(M6:M8) -> 0.013886111
B6: 1.1 Años en el mercado | C6: 0.3333 | D6: =C3*C4*C5*C6 -> 0.0055544445 | E6: Antigüedad del proveedor desde su fundación o desde el lanzamiento comercial del producto evaluado, como indicador de madurez y estabilidad en el mercado. | F6: Un proveedor con menos de 5 años representa mayor riesgo de discontinuidad o cambios disruptivos en el producto y su política comercial hacia clientes existentes. | G6: La antigüedad correlaciona con la estabilidad del producto, la madurez del soporte y la solidez financiera — factores críticos para una inversión de largo plazo. | H6: 0.75 | I6: =H6*C6 -> 0.249975 | J6: =I6*D5 -> 0.0041658334 | K6: 0.75 | L6: =K6*C6 -> 0.249975 | M6: =L6*D5 -> 0.0041658334
B7: 1.2 Presencia internacional | C7: 0.3333 | D7: =C3*C4*C5*C7 -> 0.0055544445 | E7: Operación del proveedor en múltiples países o regiones, con subsidiarias, partners certificados o clientes activos fuera de su mercado de origen. | F7: La presencia internacional indica escala y capacidad de inversión en I+D — reduce el riesgo de que decisiones locales afecten la continuidad del producto. | G7: Un proveedor con presencia global tiene mayor resistencia ante crisis regionales y más recursos para mantener y evolucionar el producto a largo plazo. | H7: 1 | I7: =H7*C7 -> 0.3333 | J7: =I7*D5 -> 0.0055544445 | K7: 1 | L7: =K7*C7 -> 0.3333 | M7: =L7*D5 -> 0.0055544445
B8: 1.3 Estabilidad financiera | C8: 0.3333 | D8: =C3*C4*C5*C8 -> 0.0055544445 | E8: Solidez financiera del proveedor: cotización pública, respaldo de inversores institucionales, ingresos recurrentes documentados o ausencia de reestructuraciones recientes. | F8: Un proveedor con dificultades financieras puede abandonar el producto, ser adquirido o degradar el servicio — riesgo crítico para la continuidad operativa. | G8: La estabilidad financiera es un componente del riesgo de vendor lock-in — un proveedor financieramente débil puede obligar a una migración forzada y costosa. | H8: 1 | I8: =H8*C8 -> 0.3333 | J8: =I8*D5 -> 0.0055544445 | K8: 0.75 | L8: =K8*C8 -> 0.249975 | M8: =L8*D5 -> 0.0041658334
B9: 2. Escala | C9: 0.3333 | D9: =C3*C4*C9 -> 0.016665 | I9: =SUM(I10:I11)*C9 -> 0.3333 | J9: =SUM(J10:J11) -> 0.016665 | L9: =SUM(L10:L11)*C9 -> 0.3333 | M9: =SUM(M10:M11) -> 0.016665
B10: 2.1 Cantidad de clientes | C10: 0.5 | D10: =C3*C4*C9*C10 -> 0.0083325 | E10: Número total de empresas clientes activas de la plataforma a nivel global o en la región, como indicador de adopción y validación en el mercado. | F10: Una base amplia de clientes indica que la plataforma superó la etapa experimental y cuenta con comunidad, recursos de soporte y ecosistema consolidado. | G10: La escala de clientes es un proxy de la madurez del producto y de la capacidad del proveedor de mantener un servicio de calidad de forma sostenible. | H10: 1 | I10: =H10*C10 -> 0.5 | J10: =I10*D9 -> 0.0083325 | K10: 1 | L10: =K10*C10 -> 0.5 | M10: =L10*D9 -> 0.0083325
B11: 2.2 Cantidad de usuarios | C11: 0.5 | D11: =C3*C4*C9*C11 -> 0.0083325 | E11: Número total de usuarios activos en la plataforma, que refleja la adopción real y la capacidad de la infraestructura para soportar carga a escala. | F11: Una plataforma con millones de usuarios activos ha probado su escalabilidad y estabilidad bajo carga real — garantía de infraestructura sólida para el cliente. | G11: La cantidad de usuarios activos valida la viabilidad técnica y comercial del proveedor a largo plazo — indicador complementario al número de clientes. | H11: 1 | I11: =H11*C11 -> 0.5 | J11: =I11*D9 -> 0.0083325 | K11: 1 | L11: =K11*C11 -> 0.5 | M11: =L11*D9 -> 0.0083325
